Compass Data: $HCHDG,299.8,,,,*48

23-10-17 17:44:18,216] ERROR in app: Exception on /get_position [GET]
Traceback (most recent call last):
  File "/usr/lib/python3/dist-packages/flask/app.py", line 2447, in wsgi_app
    response = self.full_dispatch_request()
  File "/usr/lib/python3/dist-packages/flask/app.py", line 1952, in full_dispatch_request
    rv = self.handle_user_exception(e)
  File "/usr/lib/python3/dist-packages/flask/app.py", line 1821, in handle_user_exception
    reraise(exc_type, exc_value, tb)
  File "/usr/lib/python3/dist-packages/flask/_compat.py", line 39, in reraise
    raise value
  File "/usr/lib/python3/dist-packages/flask/app.py", line 1950, in full_dispatch_request
    rv = self.dispatch_request()
  File "/usr/lib/python3/dist-packages/flask/app.py", line 1936, in dispatch_request
    return self.view_functions[rule.endpoint](**req.view_args)
  File "/home/stuart/Documents/work/modbusTest/flaskApplication.py", line 17, in get_position
    response_14 = read.read_motor_position(14)
  File "/home/stuart/Documents/work/modbusTest/read.py", line 22, in read_motor_position
    response = ser.read_holding_registers(0x1803, 1, motor_id)
  File "/usr/local/lib/python3.9/dist-packages/pymodbus/client/mixin.py", line 102, in read_holding_registers
    return self.execute(
  File "/usr/local/lib/python3.9/dist-packages/pymodbus/client/base.py", line 180, in execute
    return self.transaction.execute(request)
  File "/usr/local/lib/python3.9/dist-packages/pymodbus/transaction.py", line 168, in execute
    response, last_exception = self._transact(
  File "/usr/local/lib/python3.9/dist-packages/pymodbus/transaction.py", line 285, in _transact
    size = self._send(packet)
  File "/usr/local/lib/python3.9/dist-packages/pymodbus/transaction.py", line 325, in _send
    return self.client.framer.sendPacket(packet)
  File "/usr/local/lib/python3.9/dist-packages/pymodbus/framer/rtu_framer.py", line 286, in sendPacket
    size = self.client.send(message)
  File "/usr/local/lib/python3.9/dist-packages/pymodbus/client/serial.py", line 219, in send
    raise ConnectionException(str(self))
pymodbus.exceptions.ConnectionException: Modbus Error: [Connection] ModbusSerialClient(<pymodbus.framer.rtu_framer.ModbusRtuFramer object at 0x7faafe0d60> baud[9600])